Workbook

Sheet Clients_Churn 
A1: Source.Name | B1: ID_Client | C1: Province_Client | D1: Anciennete_Mois | E1: Type_Forfait | F1: Duree_Cumulee_Panne_Min | G1: Facture_Mensuelle | H1: Plaintes_Service_Client
A2: Clients_Churn_Part_01.xlsx | B2: CLI-01147 | C2: Ituri | D2: 29 | E2: Premium 5G 150Go | F2: 214 | G2: 74.7 | H2: 3
A3: Clients_Churn_Part_01.xlsx | B3: CLI-00894 | C3: Tshuapa | D3: 63 | E3: Pro Monde | F3: 205 | G3: 89.19 | H3: 0
A4: Clients_Churn_Part_01.xlsx | B4: CLI-00865 | C4: Mongala | D4: 34 | E4: Pro Monde | F4: 453 | G4: 56.84 | H4: 0
A5: Clients_Churn_Part_01.xlsx | B5: CLI-01325 | C5: Haut-Lomami | D5: 44 | E5: Bloqué 5Go | F5: 348 | G5: 58.67 | H5: 0
A6: Clients_Churn_Part_01.xlsx | B6: CLI-01855 | C6: Sud-Kivu | D6: 101 | E6: Illimité 50Go | F6: 358 | G6: 29.24 | H6: 3
A7: Clients_Churn_Part_01.xlsx | B7: CLI-00076 | C7: Haut-Katanga | D7: 46 | E7: Premium 5G 150Go | F7: 283 | G7: 56.05 | H7: 1
A8: Clients_Churn_Part_01.xlsx | B8: CLI-00414 | C8: Bas-Uele | D8: 99 | E8: Premium 5G 150Go | F8: 447 | G8: 38.1 | H8: 3
A9: Clients_Churn_Part_01.xlsx | B9: CLI-00327 | C9: Haut-Katanga | D9: 6 | E9: Illimité 50Go | F9: 155 | G9: 40.66 | H9: 1
A10: Clients_Churn_Part_01.xlsx | B10: CLI-00559 | C10: Kasai | D10: 99 | E10: Bloqué 5Go | F10: 369 | G10: 67.21 | H10: 3
A11: Clients_Churn_Part_01.xlsx | B11: CLI-00280 | C11: Sud-Ubangi | D11: 113 | E11: Illimité 50Go | F11: 380 | G11: 12.11 | H11: 0
A12: Clients_Churn_Part_01.xlsx | B12: CLI-00060 | C12: Kasai-Central | D12: 72 | E12: Pro Monde | F12: 160 | G12: 90.13 | H12: 2
A13: Clients_Churn_Part_01.xlsx | B13: CLI-00530 | C13: Sankuru | D13: 35 | E13: Pro Monde | F13: 465 | G13: 58.59 | H13: 5
... A398: Clients_Churn_Part_08.xlsx | B398: CLI-00576 | C398: Maniema | D398: 104 | E398: Pro Monde | F398: 60 | G398: 45.51 | H398: 1
A399: Clients_Churn_Part_08.xlsx | B399: CLI-01532 | C399: Mongala | D399: 95 | E399: Premium 5G 150Go | F399: 148 | H399: 5
A400: Clients_Churn_Part_09.xlsx | B400: CLI-00739 | C400: Kwilu | D400: 83 | E400: Premium 5G 150Go | F400: 105 | G400: 20.46 | H400: 1
A401: Clients_Churn_Part_09.xlsx | B401: CLI-00881 | C401: Lomami | D401: 7 | E401: Illimité 50Go | F401: 94 | G401: 68.38 | H401: 3
A402: Clients_Churn_Part_09.xlsx | B402: CLI-01687 | C402: Tanganyika | D402: 39 | E402: Premium 5G 150Go | F402: 1 | G402: 66.94 | H402: 5
A403: Clients_Churn_Part_09.xlsx | B403: CLI-00540 | C403: Kasai-Oriental | D403: 15 | E403: Illimité 50Go | F403: 81 | H403: 4
A404: Clients_Churn_Part_09.xlsx | B404: CLI-01256 | C404: Tshuapa | D404: 35 | E404: Pro Monde | F404: 292 | G404: 39.21 | H404: 1
A405: Clients_Churn_Part_09.xlsx | B405: CLI-01560 | C405: Ituri | D405: 47 | E405: Bloqué 5Go | F405: 111 | G405: 95.18 | H405: 0
A406: Clients_Churn_Part_09.xlsx | B406: CLI-00541 | C406: Kasai-Central | D406: 36 | E406: Bloqué 5Go | F406: 303 | G406: 89.56 | H406: 1
A407: Clients_Churn_Part_09.xlsx | B407: CLI-01059 | C407: Bas-Uele | D407: 45 | E407: Illimité 50Go | F407: 356 | G407: 33.76 | H407: 0
A408: Clients_Churn_Part_09.xlsx | B408: CLI-01606 | C408: Tanganyika | D408: 92 | E408: Bloqué 5Go | F408: 4 | G408: 22.03 | H408: 3
A409: Clients_Churn_Part_09.xlsx | B409: CLI-00893 | C409: Haut-Katanga | D409: 54 | E409: Bloqué 5Go | F409: 450 | G409: 90.85 | H409: 1
A410: Clients_Churn_Part_09.xlsx | B410: CLI-00338 | C410: Haut-Katanga | D410: 32 | E410: Illimité 50Go | F410: 475 | G410: 36.54 | H410: 3
A411: Clients_Churn_Part_09.xlsx | B411: CLI-00647 | C411: Kwilu | D411: 41 | E411: Illimité 50Go | F411: 404 | G411: 98.67 | H411: 5
A412: Clients_Churn_Part_09.xlsx | B412: CLI-01821 | C412: Tanganyika | D412: 115 | E412: Pro Monde | F412: 262 | G412: 66.34 | H412: 3
A413: Clients_Churn_Part_09.xlsx | B413: CLI-01823 | C413: Haut-Lomami | D413: 7 | E413: Bloqué 5Go | F413: 233 | G413: 10.94 | H413: 0
A414: Clients_Churn_Part_09.xlsx | B414: CLI-01565 | C414: Tshopo | D414: 24 | E414: Bloqué 5Go | F414: 257 | G414: 41.99 | H414: 5
A415: Clients_Churn_Part_09.xlsx | B415: CLI-00310 | C415: Sud-Ubangi | D415: 6 | E415: Premium 5G 150Go | F415: 362 | G415: 75.74 | H415: 4
... A492: Clients_Churn_Part_10.xlsx | B492: CLI-01766 | C492: Sud-Kivu | D492: 101 | E492: Pro Monde | F492: 210 | G492: 35.4 | H492: 1
A493: Clients_Churn_Part_10.xlsx | B493: CLI-01348 | C493: Kwango | D493: 62 | E493: Illimité 50Go | F493: 369 | H493: 1
A494: Clients_Churn_Part_10.xlsx | B494: CLI-00012 | C494: Kongo-Central | D494: 105 | E494: Illimité 50Go | F494: 172 | G494: 15.88 | H494: 5
A495: Clients_Churn_Part_10.xlsx | B495: CLI-01926 | C495: Sud-Ubangi | D495: 9 | E495: Illimité 50Go | F495: 227 | G495: 63.74 | H495: 3
A496: Clients_Churn_Part_10.xlsx | B496: CLI-00090 | C496: Mai-Ndombe | D496: 15 | E496: Bloqué 5Go | F496: 400 | G496: 78.09 | H496: 0
A497: Clients_Churn_Part_10.xlsx | B497: CLI-01344 | C497: Kasai | D497: 74 | E497: Illimité 50Go | F497: 330 | G497: 37.82 | H497: 5
A498: Clients_Churn_Part_10.xlsx | B498: CLI-01275 | C498: Ituri | D498: 55 | E498: Bloqué 5Go | F498: 355 | G498: 59.65 | H498: 0
A499: Clients_Churn_Part_10.xlsx | B499: CLI-00928 | C499: Tshopo | D499: 94 | E499: Illimité 50Go | F499: 6 | G499: 67.46 | H499: 5
A500: Clients_Churn_Part_11.xlsx | B500: CLI-00666 | C500: Mongala | D500: 120 | E500: Bloqué 5Go | F500: 27 | G500: 24.46 | H500: 3
...

Sheet Logs_Reseau
A1: Source.Name | B1: Province_RDC | C1: Date_Heure_Panne.1 | D1: Date_Heure_Panne.2 | E1: Cell_ID | F1: Duree_Panne_Min | G1: Statut_Resolution
A2: Logs_Reseau_Part_01.xlsx | B2: =_xlfn.XLOOKUP(Logs__3[[#This Row],[Cell_ID]],Registre_Maintenance[ID_Antenne],Registre_Maintenance[Province_RDC],"Pas de correspondance") -> Tanganyika | C2: 45203 | D2: 0.032638889 | E2: ANT-0465 | F2: 73 | G2: Résolu
A3: Logs_Reseau_Part_01.xlsx | B3: =_xlfn.XLOOKUP(Logs__3[[#This Row],[Cell_ID]],Registre_Maintenance[ID_Antenne],Registre_Maintenance[Province_RDC],"Pas de correspondance") -> Pas de correspondance | C3: 45208 | D3: 0.30138889 | E3: ANT-0004 | F3: 38 | G3: Résolu
A4: Logs_Reseau_Part_01.xlsx | B4: =_xlfn.XLOOKUP(Logs__3[[#This Row],[Cell_ID]],Registre_Maintenance[ID_Antenne],Registre_Maintenance[Province_RDC],"Pas de correspondance") -> Pas de correspondance | C4: 45204 | D4: 0.9625 | E4: ANT-0977 | F4: 100 | G4: Non Résolu
A5: Logs_Reseau_Part_01.xlsx | B5: =_xlfn.XLOOKUP(Logs__3[[#This Row],[Cell_ID]],Registre_Maintenance[ID_Antenne],Registre_Maintenance[Province_RDC],"Pas de correspondance") -> Pas de correspondance | C5: 45221 | D5: 0.99791667 | E5: ANT-0740 | F5: 79 | G5: En Cours
A6: Logs_Reseau_Part_01.xlsx | B6: =_xlfn.XLOOKUP(Logs__3[[#This Row],[Cell_ID]],Registre_Maintenance[ID_Antenne],Registre_Maintenance[Province_RDC],"Pas de correspondance") -> Pas de correspondance | C6: 45217 | D6: 0.10902778 | E6: ANT-0897 | F6: 59 | G6: Résolu
A7: Logs_Reseau_Part_01.xlsx | B7: =_xlfn.XLOOKUP(Logs__3[[#This Row],[Cell_ID]],Registre_Maintenance[ID_Antenne],Registre_Maintenance[Province_RDC],"Pas de correspondance") -> Kongo-Central | C7: 45213 | D7: 0.042361111 | E7: ANT-0737 | F7: 119 | G7: Non Résolu
A8: Logs_Reseau_Part_01.xlsx | B8: =_xlfn.XLOOKUP(Logs__3[[#This Row],[Cell_ID]],Registre_Maintenance[ID_Antenne],Registre_Maintenance[Province_RDC],"Pas de correspondance") -> Kasaï-Central | C8: 45202 | D8: 0.25972222 | E8: ANT-0270 | F8: 79 | G8: Résolu
A9: Logs_Reseau_Part_01.xlsx | B9: =_xlfn.XLOOKUP(Logs__3[[#This Row],[Cell_ID]],Registre_Maintenance[ID_Antenne],Registre_Maintenance[Province_RDC],"Pas de correspondance") -> Pas de correspondance | C9: 45216 | D9: 0.79236111 | E9: ANT-0996 | F9: 56 | G9: Résolu
A10: Logs_Reseau_Part_01.xlsx | B10: =_xlfn.XLOOKUP(Logs__3[[#This Row],[Cell_ID]],Registre_Maintenance[ID_Antenne],Registre_Maintenance[Province_RDC],"Pas de correspondance") -> Pas de correspondance | C10: 45217 | D10: 0.28125 | E10: ANT-0513 | F10: 51 | G10: Non Résolu
A11: Logs_Reseau_Part_01.xlsx | B11: =_xlfn.XLOOKUP(Logs__3[[#This Row],[Cell_ID]],Registre_Maintenance[ID_Antenne],Registre_Maintenance[Province_RDC],"Pas de correspondance") -> Pas de correspondance | C11: 45220 | D11: 0.94027778 | E11: ANT-0781 | F11: 33 | G11: En Cours
A12: Logs_Reseau_Part_01.xlsx | B12: =_xlfn.XLOOKUP(Logs__3[[#This Row],[Cell_ID]],Registre_Maintenance[ID_Antenne],Registre_Maintenance[Province_RDC],"Pas de correspondance") -> Pas de correspondance | C12: 45213 | D12: 0.31111111 | E12: ANT-0183 | F12: 22 | G12: Non Résolu
A13: Logs_Reseau_Part_01.xlsx | B13: =_xlfn.XLOOKUP(Logs__3[[#This Row],[Cell_ID]],Registre_Maintenance[ID_Antenne],Registre_Maintenance[Province_RDC],"Pas de correspondance") -> Lomami | C13: 45218 | D13: 0.36875 | E13: ANT-0520 | F13: 70 | G13: Résolu
... A336: Logs_Reseau_Part_08.xlsx | B336: =_xlfn.XLOOKUP(Logs__3[[#This Row],[Cell_ID]],Registre_Maintenance[ID_Antenne],Registre_Maintenance[Province_RDC],"Pas de correspondance") -> Pas de correspondance | C336: 45205 | D336: 0.79375 | E336: ANT-0406 | F336: 99 | G336: Non Résolu
A337: Logs_Reseau_Part_08.xlsx | B337: =_xlfn.XLOOKUP(Logs__3[[#This Row],[Cell_ID]],Registre_Maintenance[ID_Antenne],Registre_Maintenance[Province_RDC],"Pas de correspondance") -> Pas de correspondance | E337: ANT-0892 | F337: 10 | G337: Non Résolu
A338: Logs_Reseau_Part_08.xlsx | B338: =_xlfn.XLOOKUP(Logs__3[[#This Row],[Cell_ID]],Registre_Maintenance[ID_Antenne],Registre_Maintenance[Province_RDC],"Pas de correspondance") -> Pas de correspondance | C338: 45214 | D338: 0.89375 | E338: ANT-0318 | F338: 60 | G338: Non Résolu
A339: Logs_Reseau_Part_08.xlsx | B339: =_xlfn.XLOOKUP(Logs__3[[#This Row],[Cell_ID]],Registre_Maintenance[ID_Antenne],Registre_Maintenance[Province_RDC],"Pas de correspondance") -> Pas de correspondance | C339: 45215 | D339: 0.81111111 | E339: ANT-0764 | F339: 7 | G339: En Cours
A340: Logs_Reseau_Part_08.xlsx | B340: =_xlfn.XLOOKUP(Logs__3[[#This Row],[Cell_ID]],Registre_Maintenance[ID_Antenne],Registre_Maintenance[Province_RDC],"Pas de correspondance") -> Pas de correspondance | C340: 45213 | D340: 0.34236111 | E340: ANT-0348 | F340: 63 | G340: Non Résolu
A341: Logs_Reseau_Part_08.xlsx | B341: =_xlfn.XLOOKUP(Logs__3[[#This Row],[Cell_ID]],Registre_Maintenance[ID_Antenne],Registre_Maintenance[Province_RDC],"Pas de correspondance") -> Pas de correspondance | C341: 45224 | D341: 0.67152778 | E341: ANT-0227 | F341: 14 | G341: En Cours
A342: Logs_Reseau_Part_08.xlsx | B342: =_xlfn.XLOOKUP(Logs__3[[#This Row],[Cell_ID]],Registre_Maintenance[ID_Antenne],Registre_Maintenance[Province_RDC],"Pas de correspondance") -> Pas de correspondance | C342: 45211 | D342: 0.54652778 | E342: ANT-0342 | F342: 115 | G342: Résolu
A343: Logs_Reseau_Part_08.xlsx | B343: =_xlfn.XLOOKUP(Logs__3[[#This Row],[Cell_ID]],Registre_Maintenance[ID_Antenne],Registre_Maintenance[Province_RDC],"Pas de correspondance") -> Pas de correspondance | C343: 45209 | D343: 0.90486111 | E343: ANT-0798 | F343: 45 | G343: En Cours
A344: Logs_Reseau_Part_08.xlsx | B344: =_xlfn.XLOOKUP(Logs__3[[#This Row],[Cell_ID]],Registre_Maintenance[ID_Antenne],Registre_Maintenance[Province_RDC],"Pas de correspondance") -> Pas de correspondance | C344: 45218 | D344: 0.64791667 | E344: ANT-0173 | F344: 78 | G344: Résolu
A345: Logs_Reseau_Part_08.xlsx | B345: =_xlfn.XLOOKUP(Logs__3[[#This Row],[Cell_ID]],Registre_Maintenance[ID_Antenne],Registre_Maintenance[Province_RDC],"Pas de correspondance") -> Maniema | C345: 45221 | D345: 0.37638889 | E345: ANT-0079 | F345: 59 | G345: En Cours
A346: Logs_Reseau_Part_08.xlsx | B346: =_xlfn.XLOOKUP(Logs__3[[#This Row],[Cell_ID]],Registre_Maintenance[ID_Antenne],Registre_Maintenance[Province_RDC],"Pas de correspondance") -> Haut-Katanga | C346: 45207 | D346: 0.52638889 | E346: ANT-0523 | F346: 78 | G346: En Cours
A347: Logs_Reseau_Part_08.xlsx | B347: =_xlfn.XLOOKUP(Logs__3[[#This Row],[Cell_ID]],Registre_Maintenance[ID_Antenne],Registre_Maintenance[Province_RDC],"Pas de correspondance") -> Nord-Ubangi | C347: 45201 | D347: 0.0090277778 | E347: ANT-0649 | F347: 56 | G347: Non Résolu
A348: Logs_Reseau_Part_09.xlsx | B348: =_xlfn.XLOOKUP(Logs__3[[#This Row],[Cell_ID]],Registre_Maintenance[ID_Antenne],Registre_Maintenance[Province_RDC],"Pas de correspondance") -> Haut-Katanga | C348: 45201 | D348: 0.057638889 | E348: ANT-0989 | F348: 103 | G348: Résolu
A349: Logs_Reseau_Part_09.xlsx | B349: =_xlfn.XLOOKUP(Logs__3[[#This Row],[Cell_ID]],Registre_Maintenance[ID_Antenne],Registre_Maintenance[Province_RDC],"Pas de correspondance") -> Mongala | C349: 45226 | D349: 0.37777778 | E349: ANT-0829 | F349: 74 | G349: En Cours
... A1002: Logs_Reseau_Part_24.xlsx | B1002: =_xlfn.XLOOKUP(Logs__3[[#This Row],[Cell_ID]],Registre_Maintenance[ID_Antenne],Registre_Maintenance[Province_RDC],"Pas de correspondance") -> Pas de correspondance | C1002: 45218 | D1002: 0.66597222 | E1002: ANT-0439 | F1002: 90 | G1002: En Cours
A1003: Logs_Reseau_Part_24.xlsx | B1003: =_xlfn.XLOOKUP(Logs__3[[#This Row],[Cell_ID]],Registre_Maintenance[ID_Antenne],Registre_Maintenance[Province_RDC],"Pas de correspondance") -> Pas de correspondance | E1003: ANT-0286 | F1003: 11 | G1003: Résolu
A1004: Logs_Reseau_Part_24.xlsx | B1004: =_xlfn.XLOOKUP(Logs__3[[#This Row],[Cell_ID]],Registre_Maintenance[ID_Antenne],Registre_Maintenance[Province_RDC],"Pas de correspondance") -> Pas de correspondance | C1004: 45218 | D1004: 0.24027778 | E1004: ANT-0570 | F1004: 53 | G1004: En Cours
A1005: Logs_Reseau_Part_24.xlsx | B1005: =_xlfn.XLOOKUP(Logs__3[[#This Row],[Cell_ID]],Registre_Maintenance[ID_Antenne],Registre_Maintenance[Province_RDC],"Pas de correspondance") -> Tshuapa | C1005: 45226 | D1005: 0.17083333 | E1005: ANT-0271 | F1005: 54 | G1005: Résolu
A1006: Logs_Reseau_Part_24.xlsx | B1006: =_xlfn.XLOOKUP(Logs__3[[#This Row],[Cell_ID]],Registre_Maintenance[ID_Antenne],Registre_Maintenance[Province_RDC],"Pas de correspondance") -> Kwango | C1006: 45212 | D1006: 0.90138889 | E1006: ANT-0134 | F1006: 58 | G1006: Résolu
A1007: Logs_Reseau_Part_24.xlsx | B1007: =_xlfn.XLOOKUP(Logs__3[[#This Row],[Cell_ID]],Registre_Maintenance[ID_Antenne],Registre_Maintenance[Province_RDC],"Pas de correspondance") -> Sud-Ubangi | C1007: 45219 | D1007: 0.43888889 | E1007: ANT-0165 | F1007: 105 | G1007: Non Résolu
A1008: Logs_Reseau_Part_24.xlsx | B1008: =_xlfn.XLOOKUP(Logs__3[[#This Row],[Cell_ID]],Registre_Maintenance[ID_Antenne],Registre_Maintenance[Province_RDC],"Pas de correspondance") -> Pas de correspondance | C1008: 45228 | D1008: 0.51805556 | E1008: ANT-0599 | F1008: 92 | G1008: En Cours
A1009: Logs_Reseau_Part_24.xlsx | B1009: =_xlfn.XLOOKUP(Logs__3[[#This Row],[Cell_ID]],Registre_Maintenance[ID_Antenne],Registre_Maintenance[Province_RDC],"Pas de correspondance") -> Pas de correspondance | C1009: 45219 | D1009: 0.95 | E1009: ANT-0867 | F1009: 45 | G1009: En Cours
A1010: Logs_Reseau_Part_24.xlsx | B1010: =_xlfn.XLOOKUP(Logs__3[[#This Row],[Cell_ID]],Registre_Maintenance[ID_Antenne],Registre_Maintenance[Province_RDC],"Pas de correspondance") -> Pas de correspondance | C1010: 45207 | D1010: 0.35069444 | E1010: ANT-0262 | F1010: 75 | G1010: En Cours
A1011: Logs_Reseau_Part_24.xlsx | B1011: =_xlfn.XLOOKUP(Logs__3[[#This Row],[Cell_ID]],Registre_Maintenance[ID_Antenne],Registre_Maintenance[Province_RDC],"Pas de correspondance") -> Bas-Uele | C1011: 45230 | D1011: 0.42916667 | E1011: ANT-0006 | F1011: 11 | G1011: En Cours
A1012: Logs_Reseau_Part_24.xlsx | B1012: =_xlfn.XLOOKUP(Logs__3[[#This Row],[Cell_ID]],Registre_Maintenance[ID_Antenne],Registre_Maintenance[Province_RDC],"Pas de correspondance") -> Bas-Uele | C1012: 45214 | D1012: 0.17222222 | E1012: ANT-0339 | F1012: 6 | G1012: Résolu
A1013: Logs_Reseau_Part_24.xlsx | B1013: =_xlfn.XLOOKUP(Logs__3[[#This Row],[Cell_ID]],Registre_Maintenance[ID_Antenne],Registre_Maintenance[Province_RDC],"Pas de correspondance") -> Pas de correspondance | C1013: 45213 | D1013: 0.82222222 | E1013: ANT-0478 | F1013: 100 | G1013: Non Résolu
A1014: Logs_Reseau_Part_24.xlsx | B1014: =_xlfn.XLOOKUP(Logs__3[[#This Row],[Cell_ID]],Registre_Maintenance[ID_Antenne],Registre_Maintenance[Province_RDC],"Pas de correspondance") -> Pas de correspondance | C1014: 45228 | D1014: 0.98055556 | E1014: ANT-0727 | F1014: 37 | G1014: Non Résolu
...

Sheet Registre_Maintenance
A1: Source.Name | B1: ID_Antenne | C1: Province_RDC | D1: Latitude | E1: Longitude | F1: Technologie | G1: Equipementier
A2: Registre_Maintenance_Part_01.xlsx | B2: ANT-0622 | C2: Haut-Uele | D2: -3.003879 | E2: 23.633893 | F2: 5G | G2: Ericsson
A3: Registre_Maintenance_Part_01.xlsx | B3: ANT-0084 | C3: Kwilu | D3: 2.413557 | E3: 19.690682 | F3: 4G | G3: Huawei
A4: Registre_Maintenance_Part_01.xlsx | B4: ANT-0862 | C4: Tanganyika | D4: -9.470862 | E4: 29.234388 | F4: 3G | G4: ZTE
A5: Registre_Maintenance_Part_01.xlsx | B5: ANT-0288 | C5: Tshopo | D5: 1.400674 | E5: 13.503127 | F5: 5G | G5: ZTE
A6: Registre_Maintenance_Part_01.xlsx | B6: ANT-0880 | C6: Haut-Uele | D6: 0.293756 | E6: 18.528884 | F6: 5G | G6: ZTE
A7: Registre_Maintenance_Part_01.xlsx | B7: ANT-0847 | C7: Maniema | D7: -4.486234 | E7: 17.956159 | F7: 3G | G7: Huawei
A8: Registre_Maintenance_Part_01.xlsx | B8: ANT-0144 | C8: Tanganyika | D8: -12.824639 | E8: 24.407249 | F8: 5G | G8: Huawei
A9: Registre_Maintenance_Part_01.xlsx | B9: ANT-0913 | C9: Kinshasa | D9: -5.412628 | E9: 25.498236 | F9: 5G | G9: ZTE
A10: Registre_Maintenance_Part_01.xlsx | B10: ANT-0552 | C10: Kinshasa | D10: -10.57951 | E10: 23.502314 | F10: 4G | G10: ZTE
A11: Registre_Maintenance_Part_01.xlsx | B11: ANT-0202 | C11: Tshuapa | D11: 3.078867 | E11: 19.513651 | F11: 5G | G11: Huawei
A12: Registre_Maintenance_Part_01.xlsx | B12: ANT-0270 | C12: Kasaï-Central | D12: -1.648264 | E12: 28.866144 | F12: 5G | G12: Ericsson
A13: Registre_Maintenance_Part_01.xlsx | B13: ANT-0752 | C13: Nord-Kivu | D13: -3.388313 | E13: 26.838507 | F13: 5G | G13: Nokia
... A400: Registre_Maintenance_Part_08.xlsx | B400: ANT-0357 | C400: Tanganyika | D400: -11.793894 | E400: 20.433341 | F400: 5G | G400: Nokia

Sheet Clients_Log
A1: Source.Name | B1: ID_Client | C1: Cell_ID | D1: Province_Client | E1: Anciennete_Mois | F1: Type_Forfait | G1: Duree_Cumulee_Panne_Min | H1: Facture_Mensuelle | I1: Plaintes_Service_Client
A2: Clients_Churn_Part_01.xlsx | B2: CLI-01147 | C2: =_xlfn.XLOOKUP(Clients_Churn[[#This Row],[Province_Client]],Logs_Reseau!B:B,Logs_Reseau!E:E,"Pas de correspondance") -> ANT-0037 | D2: Ituri | E2: 29 | F2: Premium 5G 150Go | G2: 214 | H2: 74.7 | I2: 3
A3: Clients_Churn_Part_01.xlsx | B3: CLI-00894 | C3: =_xlfn.XLOOKUP(Clients_Churn[[#This Row],[Province_Client]],Logs_Reseau!B:B,Logs_Reseau!E:E,"Pas de correspondance") -> ANT-0271 | D3: Tshuapa | E3: 63 | F3: Pro Monde | G3: 205 | H3: 89.19 | I3: 0
A4: Clients_Churn_Part_01.xlsx | B4: CLI-00865 | C4: =_xlfn.XLOOKUP(Clients_Churn[[#This Row],[Province_Client]],Logs_Reseau!B:B,Logs_Reseau!E:E,"Pas de correspondance") -> ANT-0855 | D4: Mongala | E4: 34 | F4: Pro Monde | G4: 453 | H4: 56.84 | I4: 0
A5: Clients_Churn_Part_01.xlsx | B5: CLI-01325 | C5: =_xlfn.XLOOKUP(Clients_Churn[[#This Row],[Province_Client]],Logs_Reseau!B:B,Logs_Reseau!E:E,"Pas de correspondance") -> ANT-0371 | D5: Haut-Lomami | E5: 44 | F5: Bloqué 5Go | G5: 348 | H5: 58.67 | I5: 0
A6: Clients_Churn_Part_01.xlsx | B6: CLI-01855 | C6: =_xlfn.XLOOKUP(Clients_Churn[[#This Row],[Province_Client]],Logs_Reseau!B:B,Logs_Reseau!E:E,"Pas de correspondance") -> ANT-0852 | D6: Sud-Kivu | E6: 101 | F6: Illimité 50Go | G6: 358 | H6: 29.24 | I6: 3
A7: Clients_Churn_Part_01.xlsx | B7: CLI-00076 | C7: =_xlfn.XLOOKUP(Clients_Churn[[#This Row],[Province_Client]],Logs_Reseau!B:B,Logs_Reseau!E:E,"Pas de correspondance") -> ANT-0624 | D7: Haut-Katanga | E7: 46 | F7: Premium 5G 150Go | G7: 283 | H7: 56.05 | I7: 1
A8: Clients_Churn_Part_01.xlsx | B8: CLI-00414 | C8: =_xlfn.XLOOKUP(Clients_Churn[[#This Row],[Province_Client]],Logs_Reseau!B:B,Logs_Reseau!E:E,"Pas de correspondance") -> ANT-0566 | D8: Bas-Uele | E8: 99 | F8: Premium 5G 150Go | G8: 447 | H8: 38.1 | I8: 3
A9: Clients_Churn_Part_01.xlsx | B9: CLI-00327 | C9: =_xlfn.XLOOKUP(Clients_Churn[[#This Row],[Province_Client]],Logs_Reseau!B:B,Logs_Reseau!E:E,"Pas de correspondance") -> ANT-0624 | D9: Haut-Katanga | E9: 6 | F9: Illimité 50Go | G9: 155 | H9: 40.66 | I9: 1
A10: Clients_Churn_Part_01.xlsx | B10: CLI-00559 | C10: =_xlfn.XLOOKUP(Clients_Churn[[#This Row],[Province_Client]],Logs_Reseau!B:B,Logs_Reseau!E:E,"Pas de correspondance") -> ANT-0332 | D10: Kasaï | E10: 99 | F10: Bloqué 5Go | G10: 369 | H10: 67.21 | I10: 3
A11: Clients_Churn_Part_01.xlsx | B11: CLI-00280 | C11: =_xlfn.XLOOKUP(Clients_Churn[[#This Row],[Province_Client]],Logs_Reseau!B:B,Logs_Reseau!E:E,"Pas de correspondance") -> ANT-0166 | D11: Sud-Ubangi | E11: 113 | F11: Illimité 50Go | G11: 380 | H11: 12.11 | I11: 0
A12: Clients_Churn_Part_01.xlsx | B12: CLI-00060 | C12: =_xlfn.XLOOKUP(Clients_Churn[[#This Row],[Province_Client]],Logs_Reseau!B:B,Logs_Reseau!E:E,"Pas de correspondance") -> ANT-0270 | D12: Kasaï-Central | E12: 72 | F12: Pro Monde | G12: 160 | H12: 90.13 | I12: 2
A13: Clients_Churn_Part_01.xlsx | B13: CLI-00530 | C13: =_xlfn.XLOOKUP(Clients_Churn[[#This Row],[Province_Client]],Logs_Reseau!B:B,Logs_Reseau!E:E,"Pas de correspondance") -> ANT-0760 | D13: Sankuru | E13: 35 | F13: Pro Monde | G13: 465 | H13: 58.59 | I13: 5
... A745: Clients_Churn_Part_15.xlsx | B745: CLI-00800 | C745: =_xlfn.XLOOKUP(Clients_Churn[[#This Row],[Province_Client]],Logs_Reseau!B:B,Logs_Reseau!E:E,"Pas de correspondance") -> ANT-0553 | D745: Nord-Kivu | E745: 4 | F745: Bloqué 5Go | G745: 21 | H745: 45.8 | I745: 1

Sheet Logs_Registre
A1: Source.Name | B1: Date_Panne | C1: Heure_Panne | D1: Cell_ID | E1: Duree_Panne_Min | F1: Statut_Resolution | G1: Province_RDC | H1: Latitude | I1: Longitude | J1: Technologie | K1: Equipementier
A2: Logs_Reseau_Part_01.xlsx | B2: 45203 | C2: 0.032638889 | D2: ANT-0465 | E2: 73 | F2: Résolu | G2: =_xlfn.XLOOKUP(Logs__2[[#This Row],[Cell_ID]],'Registre_Maintenance'!B:B,'Registre_Maintenance'!C:C,"Pas de correspondance") -> Tanganyika | H2: =_xlfn.XLOOKUP(Logs__2[[#This Row],[Cell_ID]],'Registre_Maintenance'!B:B,'Registre_Maintenance'!D:D,"Pas de correspondance") -> -11.144149 | I2: =_xlfn.XLOOKUP(Logs__2[[#This Row],[Cell_ID]],'Registre_Maintenance'!B:B,'Registre_Maintenance'!E:E,"Pas de correspondance") -> 27.244659 | J2: =_xlfn.XLOOKUP(Logs__2[[#This Row],[Cell_ID]],'Registre_Maintenance'!B:B,'Registre_Maintenance'!F:F,"Pas de correspondance") -> 4G | K2: =_xlfn.XLOOKUP(Logs__2[[#This Row],[Cell_ID]],'Registre_Maintenance'!B:B,'Registre_Maintenance'!G:G,"Pas de correspondance") -> Nokia
A3: Logs_Reseau_Part_01.xlsx | B3: 45208 | C3: 0.30138889 | D3: ANT-0004 | E3: 38 | F3: Résolu | G3: =_xlfn.XLOOKUP(Logs__2[[#This Row],[Cell_ID]],'Registre_Maintenance'!B:B,'Registre_Maintenance'!C:C,"Pas de correspondance") -> Pas de correspondance | H3: =_xlfn.XLOOKUP(Logs__2[[#This Row],[Cell_ID]],'Registre_Maintenance'!B:B,'Registre_Maintenance'!D:D,"Pas de correspondance") -> Pas de correspondance | I3: =_xlfn.XLOOKUP(Logs__2[[#This Row],[Cell_ID]],'Registre_Maintenance'!B:B,'Registre_Maintenance'!E:E,"Pas de correspondance") -> Pas de correspondance | J3: =_xlfn.XLOOKUP(Logs__2[[#This Row],[Cell_ID]],'Registre_Maintenance'!B:B,'Registre_Maintenance'!F:F,"Pas de correspondance") -> Pas de correspondance | K3: =_xlfn.XLOOKUP(Logs__2[[#This Row],[Cell_ID]],'Registre_Maintenance'!B:B,'Registre_Maintenance'!G:G,"Pas de correspondance") -> Pas de correspondance
A4: Logs_Reseau_Part_01.xlsx | B4: 45204 | C4: 0.9625 | D4: ANT-0977 | E4: 100 | F4: Non Résolu | G4: =_xlfn.XLOOKUP(Logs__2[[#This Row],[Cell_ID]],'Registre_Maintenance'!B:B,'Registre_Maintenance'!C:C,"Pas de correspondance") -> Pas de correspondance | H4: =_xlfn.XLOOKUP(Logs__2[[#This Row],[Cell_ID]],'Registre_Maintenance'!B:B,'Registre_Maintenance'!D:D,"Pas de correspondance") -> Pas de correspondance | I4: =_xlfn.XLOOKUP(Logs__2[[#This Row],[Cell_ID]],'Registre_Maintenance'!B:B,'Registre_Maintenance'!E:E,"Pas de correspondance") -> Pas de correspondance | J4: =_xlfn.XLOOKUP(Logs__2[[#This Row],[Cell_ID]],'Registre_Maintenance'!B:B,'Registre_Maintenance'!F:F,"Pas de correspondance") -> Pas de correspondance | K4: =_xlfn.XLOOKUP(Logs__2[[#This Row],[Cell_ID]],'Registre_Maintenance'!B:B,'Registre_Maintenance'!G:G,"Pas de correspondance") -> Pas de correspondance
A5: Logs_Reseau_Part_01.xlsx | B5: 45221 | C5: 0.99791667 | D5: ANT-0740 | E5: 79 | F5: En Cours | G5: =_xlfn.XLOOKUP(Logs__2[[#This Row],[Cell_ID]],'Registre_Maintenance'!B:B,'Registre_Maintenance'!C:C,"Pas de correspondance") -> Pas de correspondance | H5: =_xlfn.XLOOKUP(Logs__2[[#This Row],[Cell_ID]],'Registre_Maintenance'!B:B,'Registre_Maintenance'!D:D,"Pas de correspondance") -> Pas de correspondance | I5: =_xlfn.XLOOKUP(Logs__2[[#This Row],[Cell_ID]],'Registre_Maintenance'!B:B,'Registre_Maintenance'!E:E,"Pas de correspondance") -> Pas de correspondance | J5: =_xlfn.XLOOKUP(Logs__2[[#This Row],[Cell_ID]],'Registre_Maintenance'!B:B,'Registre_Maintenance'!F:F,"Pas de correspondance") -> Pas de correspondance | K5: =_xlfn.XLOOKUP(Logs__2[[#This Row],[Cell_ID]],'Registre_Maintenance'!B:B,'Registre_Maintenance'!G:G,"Pas de correspondance") -> Pas de correspondance
A6: Logs_Reseau_Part_01.xlsx | B6: 45217 | C6: 0.10902778 | D6: ANT-0897 | E6: 59 | F6: Résolu | G6: =_xlfn.XLOOKUP(Logs__2[[#This Row],[Cell_ID]],'Registre_Maintenance'!B:B,'Registre_Maintenance'!C:C,"Pas de correspondance") -> Pas de correspondance | H6: =_xlfn.XLOOKUP(Logs__2[[#This Row],[Cell_ID]],'Registre_Maintenance'!B:B,'Registre_Maintenance'!D:D,"Pas de correspondance") -> Pas de correspondance | I6: =_xlfn.XLOOKUP(Logs__2[[#This Row],[Cell_ID]],'Registre_Maintenance'!B:B,'Registre_Maintenance'!E:E,"Pas de correspondance") -> Pas de correspondance | J6: =_xlfn.XLOOKUP(Logs__2[[#This Row],[Cell_ID]],'Registre_Maintenance'!B:B,'Registre_Maintenance'!F:F,"Pas de correspondance") -> Pas de correspondance | K6: =_xlfn.XLOOKUP(Logs__2[[#This Row],[Cell_ID]],'Registre_Maintenance'!B:B,'Registre_Maintenance'!G:G,"Pas de correspondance") -> Pas de correspondance
A7: Logs_Reseau_Part_01.xlsx | B7: 45213 | C7: 0.042361111 | D7: ANT-0737 | E7: 119 | F7: Non Résolu | G7: =_xlfn.XLOOKUP(Logs__2[[#This Row],[Cell_ID]],'Registre_Maintenance'!B:B,'Registre_Maintenance'!C:C,"Pas de correspondance") -> Kongo-Central | H7: =_xlfn.XLOOKUP(Logs__2[[#This Row],[Cell_ID]],'Registre_Maintenance'!B:B,'Registre_Maintenance'!D:D,"Pas de correspondance") -> -2.821152 | I7: =_xlfn.XLOOKUP(Logs__2[[#This Row],[Cell_ID]],'Registre_Maintenance'!B:B,'Registre_Maintenance'!E:E,"Pas de correspondance") -> 20.651419 | J7: =_xlfn.XLOOKUP(Logs__2[[#This Row],[Cell_ID]],'Registre_Maintenance'!B:B,'Registre_Maintenance'!F:F,"Pas de correspondance") -> 5G | K7: =_xlfn.XLOOKUP(Logs__2[[#This Row],[Cell_ID]],'Registre_Maintenance'!B:B,'Registre_Maintenance'!G:G,"Pas de correspondance") -> Ericsson
A8: Logs_Reseau_Part_01.xlsx | B8: 45202 | C8: 0.25972222 | D8: ANT-0270 | E8: 79 | F8: Résolu | G8: =_xlfn.XLOOKUP(Logs__2[[#This Row],[Cell_ID]],'Registre_Maintenance'!B:B,'Registre_Maintenance'!C:C,"Pas de correspondance") -> Kasaï-Central | H8: =_xlfn.XLOOKUP(Logs__2[[#This Row],[Cell_ID]],'Registre_Maintenance'!B:B,'Registre_Maintenance'!D:D,"Pas de correspondance") -> -1.648264 | I8: =_xlfn.XLOOKUP(Logs__2[[#This Row],[Cell_ID]],'Registre_Maintenance'!B:B,'Registre_Maintenance'!E:E,"Pas de correspondance") -> 28.866144 | J8: =_xlfn.XLOOKUP(Logs__2[[#This Row],[Cell_ID]],'Registre_Maintenance'!B:B,'Registre_Maintenance'!F:F,"Pas de correspondance") -> 5G | K8: =_xlfn.XLOOKUP(Logs__2[[#This Row],[Cell_ID]],'Registre_Maintenance'!B:B,'Registre_Maintenance'!G:G,"Pas de correspondance") -> Ericsson
A9: Logs_Reseau_Part_01.xlsx | B9: 45216 | C9: 0.79236111 | D9: ANT-0996 | E9: 56 | F9: Résolu | G9: =_xlfn.XLOOKUP(Logs__2[[#This Row],[Cell_ID]],'Registre_Maintenance'!B:B,'Registre_Maintenance'!C:C,"Pas de correspondance") -> Pas de correspondance | H9: =_xlfn.XLOOKUP(Logs__2[[#This Row],[Cell_ID]],'Registre_Maintenance'!B:B,'Registre_Maintenance'!D:D,"Pas de correspondance") -> Pas de correspondance | I9: =_xlfn.XLOOKUP(Logs__2[[#This Row],[Cell_ID]],'Registre_Maintenance'!B:B,'Registre_Maintenance'!E:E,"Pas de correspondance") -> Pas de correspondance | J9: =_xlfn.XLOOKUP(Logs__2[[#This Row],[Cell_ID]],'Registre_Maintenance'!B:B,'Registre_Maintenance'!F:F,"Pas de correspondance") -> Pas de correspondance | K9: =_xlfn.XLOOKUP(Logs__2[[#This Row],[Cell_ID]],'Registre_Maintenance'!B:B,'Registre_Maintenance'!G:G,"Pas de correspondance") -> Pas de correspondance
A10: Logs_Reseau_Part_01.xlsx | B10: 45217 | C10: 0.28125 | D10: ANT-0513 | E10: 51 | F10: Non Résolu | G10: =_xlfn.XLOOKUP(Logs__2[[#This Row],[Cell_ID]],'Registre_Maintenance'!B:B,'Registre_Maintenance'!C:C,"Pas de correspondance") -> Pas de correspondance | H10: =_xlfn.XLOOKUP(Logs__2[[#This Row],[Cell_ID]],'Registre_Maintenance'!B:B,'Registre_Maintenance'!D:D,"Pas de correspondance") -> Pas de correspondance | I10: =_xlfn.XLOOKUP(Logs__2[[#This Row],[Cell_ID]],'Registre_Maintenance'!B:B,'Registre_Maintenance'!E:E,"Pas de correspondance") -> Pas de correspondance | J10: =_xlfn.XLOOKUP(Logs__2[[#This Row],[Cell_ID]],'Registre_Maintenance'!B:B,'Registre_Maintenance'!F:F,"Pas de correspondance") -> Pas de correspondance | K10: =_xlfn.XLOOKUP(Logs__2[[#This Row],[Cell_ID]],'Registre_Maintenance'!B:B,'Registre_Maintenance'!G:G,"Pas de correspondance") -> Pas de correspondance
A11: Logs_Reseau_Part_01.xlsx | B11: 45220 | C11: 0.94027778 | D11: ANT-0781 | E11: 33 | F11: En Cours | G11: =_xlfn.XLOOKUP(Logs__2[[#This Row],[Cell_ID]],'Registre_Maintenance'!B:B,'Registre_Maintenance'!C:C,"Pas de correspondance") -> Pas de correspondance | H11: =_xlfn.XLOOKUP(Logs__2[[#This Row],[Cell_ID]],'Registre_Maintenance'!B:B,'Registre_Maintenance'!D:D,"Pas de correspondance") -> Pas de correspondance | I11: =_xlfn.XLOOKUP(Logs__2[[#This Row],[Cell_ID]],'Registre_Maintenance'!B:B,'Registre_Maintenance'!E:E,"Pas de correspondance") -> Pas de correspondance | J11: =_xlfn.XLOOKUP(Logs__2[[#This Row],[Cell_ID]],'Registre_Maintenance'!B:B,'Registre_Maintenance'!F:F,"Pas de correspondance") -> Pas de correspondance | K11: =_xlfn.XLOOKUP(Logs__2[[#This Row],[Cell_ID]],'Registre_Maintenance'!B:B,'Registre_Maintenance'!G:G,"Pas de correspondance") -> Pas de correspondance
A12: Logs_Reseau_Part_01.xlsx | B12: 45213 | C12: 0.31111111 | D12: ANT-0183 | E12: 22 | F12: Non Résolu | G12: =_xlfn.XLOOKUP(Logs__2[[#This Row],[Cell_ID]],'Registre_Maintenance'!B:B,'Registre_Maintenance'!C:C,"Pas de correspondance") -> Pas de correspondance | H12: =_xlfn.XLOOKUP(Logs__2[[#This Row],[Cell_ID]],'Registre_Maintenance'!B:B,'Registre_Maintenance'!D:D,"Pas de correspondance") -> Pas de correspondance | I12: =_xlfn.XLOOKUP(Logs__2[[#This Row],[Cell_ID]],'Registre_Maintenance'!B:B,'Registre_Maintenance'!E:E,"Pas de correspondance") -> Pas de correspondance | J12: =_xlfn.XLOOKUP(Logs__2[[#This Row],[Cell_ID]],'Registre_Maintenance'!B:B,'Registre_Maintenance'!F:F,"Pas de correspondance") -> Pas de correspondance | K12: =_xlfn.XLOOKUP(Logs__2[[#This Row],[Cell_ID]],'Registre_Maintenance'!B:B,'Registre_Maintenance'!G:G,"Pas de correspondance") -> Pas de correspondance
A13: Logs_Reseau_Part_01.xlsx | B13: 45218 | C13: 0.36875 | D13: ANT-0520 | E13: 70 | F13: Résolu | G13: =_xlfn.XLOOKUP(Logs__2[[#This Row],[Cell_ID]],'Registre_Maintenance'!B:B,'Registre_Maintenance'!C:C,"Pas de correspondance") -> Lomami | H13: =_xlfn.XLOOKUP(Logs__2[[#This Row],[Cell_ID]],'Registre_Maintenance'!B:B,'Registre_Maintenance'!D:D,"Pas de correspondance") -> -8.422786 | I13: =_xlfn.XLOOKUP(Logs__2[[#This Row],[Cell_ID]],'Registre_Maintenance'!B:B,'Registre_Maintenance'!E:E,"Pas de correspondance") -> 16.781293 | J13: =_xlfn.XLOOKUP(Logs__2[[#This Row],[Cell_ID]],'Registre_Maintenance'!B:B,'Registre_Maintenance'!F:F,"Pas de correspondance") -> 4G | K13: =_xlfn.XLOOKUP(Logs__2[[#This Row],[Cell_ID]],'Registre_Maintenance'!B:B,'Registre_Maintenance'!G:G,"Pas de correspondance") -> Huawei
... A1078: Logs_Reseau_Part_25.xlsx | B1078: 45229 | C1078: 0.98680556 | D1078: ANT-0635 | E1078: 37 | F1078: En Cours | G1078: =_xlfn.XLOOKUP(Logs__2[[#This Row],[Cell_ID]],'Registre_Maintenance'!B:B,'Registre_Maintenance'!C:C,"Pas de correspondance") -> Pas de correspondance | H1078: =_xlfn.XLOOKUP(Logs__2[[#This Row],[Cell_ID]],'Registre_Maintenance'!B:B,'Registre_Maintenance'!D:D,"Pas de correspondance") -> Pas de correspondance | I1078: =_xlfn.XLOOKUP(Logs__2[[#This Row],[Cell_ID]],'Registre_Maintenance'!B:B,'Registre_Maintenance'!E:E,"Pas de correspondance") -> Pas de correspondance | J1078: =_xlfn.XLOOKUP(Logs__2[[#This Row],[Cell_ID]],'Registre_Maintenance'!B:B,'Registre_Maintenance'!F:F,"Pas de correspondance") -> Pas de correspondance | K1078: =_xlfn.XLOOKUP(Logs__2[[#This Row],[Cell_ID]],'Registre_Maintenance'!B:B,'Registre_Maintenance'!G:G,"Pas de correspondance") -> Pas de correspondance

Sheet Registre_Log
A1: Source.Name | B1: ID_Antenne | C1: Province_RDC | D1: Latitude | E1: Longitude | F1: Technologie | G1: Equipementier | H1: Date_Panne | I1: Heure_Panne | J1: Duree_Panne_Min | K1: Statut_Resolution
A2: Registre_Maintenance_Part_01.xlsx | B2: ANT-0622 | C2: Haut-Uele | D2: -3.003879 | E2: 23.633893 | F2: 5G | G2: Ericsson | H2: =_xlfn.XLOOKUP(Registre_Maintenance__2[[#This Row],[ID_Antenne]],Master!D:D,Master!B:B,"Pas de correspondance") -> Pas de correspondance | I2: =_xlfn.XLOOKUP(Registre_Maintenance__2[[#This Row],[ID_Antenne]],Master!D:D,Master!C:C,"Pas de correspondance") -> Pas de correspondance | J2: =_xlfn.XLOOKUP(Registre_Maintenance__2[[#This Row],[ID_Antenne]],Master!D:D,Master!F:F,"Pas de correspondance") -> Pas de correspondance | K2: =_xlfn.XLOOKUP(Registre_Maintenance__2[[#This Row],[ID_Antenne]],Master!D:D,Master!#REF!,"Pas de correspondance") -> #REF!
A3: Registre_Maintenance_Part_01.xlsx | B3: ANT-0084 | C3: Kwilu | D3: 2.413557 | E3: 19.690682 | F3: 4G | G3: Huawei | H3: =_xlfn.XLOOKUP(Registre_Maintenance__2[[#This Row],[ID_Antenne]],Master!D:D,Master!B:B,"Pas de correspondance") -> Pas de correspondance | I3: =_xlfn.XLOOKUP(Registre_Maintenance__2[[#This Row],[ID_Antenne]],Master!D:D,Master!C:C,"Pas de correspondance") -> Pas de correspondance | J3: =_xlfn.XLOOKUP(Registre_Maintenance__2[[#This Row],[ID_Antenne]],Master!D:D,Master!F:F,"Pas de correspondance") -> Pas de correspondance | K3: =_xlfn.XLOOKUP(Registre_Maintenance__2[[#This Row],[ID_Antenne]],Master!D:D,Master!#REF!,"Pas de correspondance") -> #REF!
A4: Registre_Maintenance_Part_01.xlsx | B4: ANT-0862 | C4: Tanganyika | D4: -9.470862 | E4: 29.234388 | F4: 3G | G4: ZTE | H4: =_xlfn.XLOOKUP(Registre_Maintenance__2[[#This Row],[ID_Antenne]],Master!D:D,Master!B:B,"Pas de correspondance") -> Pas de correspondance | I4: =_xlfn.XLOOKUP(Registre_Maintenance__2[[#This Row],[ID_Antenne]],Master!D:D,Master!C:C,"Pas de correspondance") -> Pas de correspondance | J4: =_xlfn.XLOOKUP(Registre_Maintenance__2[[#This Row],[ID_Antenne]],Master!D:D,Master!F:F,"Pas de correspondance") -> Pas de correspondance | K4: =_xlfn.XLOOKUP(Registre_Maintenance__2[[#This Row],[ID_Antenne]],Master!D:D,Master!#REF!,"Pas de correspondance") -> #REF!
A5: Registre_Maintenance_Part_01.xlsx | B5: ANT-0288 | C5: Tshopo | D5: 1.400674 | E5: 13.503127 | F5: 5G | G5: ZTE | H5: =_xlfn.XLOOKUP(Registre_Maintenance__2[[#This Row],[ID_Antenne]],Master!D:D,Master!B:B,"Pas de correspondance") -> Pas de correspondance | I5: =_xlfn.XLOOKUP(Registre_Maintenance__2[[#This Row],[ID_Antenne]],Master!D:D,Master!C:C,"Pas de correspondance") -> Pas de correspondance | J5: =_xlfn.XLOOKUP(Registre_Maintenance__2[[#This Row],[ID_Antenne]],Master!D:D,Master!F:F,"Pas de correspondance") -> Pas de correspondance | K5: =_xlfn.XLOOKUP(Registre_Maintenance__2[[#This Row],[ID_Antenne]],Master!D:D,Master!#REF!,"Pas de correspondance") -> #REF!
A6: Registre_Maintenance_Part_01.xlsx | B6: ANT-0880 | C6: Haut-Uele | D6: 0.293756 | E6: 18.528884 | F6: 5G | G6: ZTE | H6: =_xlfn.XLOOKUP(Registre_Maintenance__2[[#This Row],[ID_Antenne]],Master!D:D,Master!B:B,"Pas de correspondance") -> Pas de correspondance | I6: =_xlfn.XLOOKUP(Registre_Maintenance__2[[#This Row],[ID_Antenne]],Master!D:D,Master!C:C,"Pas de correspondance") -> Pas de correspondance | J6: =_xlfn.XLOOKUP(Registre_Maintenance__2[[#This Row],[ID_Antenne]],Master!D:D,Master!F:F,"Pas de correspondance") -> Pas de correspondance | K6: =_xlfn.XLOOKUP(Registre_Maintenance__2[[#This Row],[ID_Antenne]],Master!D:D,Master!#REF!,"Pas de correspondance") -> #REF!
A7: Registre_Maintenance_Part_01.xlsx | B7: ANT-0847 | C7: Maniema | D7: -4.486234 | E7: 17.956159 | F7: 3G | G7: Huawei | H7: =_xlfn.XLOOKUP(Registre_Maintenance__2[[#This Row],[ID_Antenne]],Master!D:D,Master!B:B,"Pas de correspondance") -> Pas de correspondance | I7: =_xlfn.XLOOKUP(Registre_Maintenance__2[[#This Row],[ID_Antenne]],Master!D:D,Master!C:C,"Pas de correspondance") -> Pas de correspondance | J7: =_xlfn.XLOOKUP(Registre_Maintenance__2[[#This Row],[ID_Antenne]],Master!D:D,Master!F:F,"Pas de correspondance") -> Pas de correspondance | K7: =_xlfn.XLOOKUP(Registre_Maintenance__2[[#This Row],[ID_Antenne]],Master!D:D,Master!#REF!,"Pas de correspondance") -> #REF!
A8: Registre_Maintenance_Part_01.xlsx | B8: ANT-0144 | C8: Tanganyika | D8: -12.824639 | E8: 24.407249 | F8: 5G | G8: Huawei | H8: =_xlfn.XLOOKUP(Registre_Maintenance__2[[#This Row],[ID_Antenne]],Master!D:D,Master!B:B,"Pas de correspondance") -> Pas de correspondance | I8: =_xlfn.XLOOKUP(Registre_Maintenance__2[[#This Row],[ID_Antenne]],Master!D:D,Master!C:C,"Pas de correspondance") -> Pas de correspondance | J8: =_xlfn.XLOOKUP(Registre_Maintenance__2[[#This Row],[ID_Antenne]],Master!D:D,Master!F:F,"Pas de correspondance") -> Pas de correspondance | K8: =_xlfn.XLOOKUP(Registre_Maintenance__2[[#This Row],[ID_Antenne]],Master!D:D,Master!#REF!,"Pas de correspondance") -> #REF!
A9: Registre_Maintenance_Part_01.xlsx | B9: ANT-0913 | C9: Kinshasa | D9: -5.412628 | E9: 25.498236 | F9: 5G | G9: ZTE | H9: =_xlfn.XLOOKUP(Registre_Maintenance__2[[#This Row],[ID_Antenne]],Master!D:D,Master!B:B,"Pas de correspondance") -> Pas de correspondance | I9: =_xlfn.XLOOKUP(Registre_Maintenance__2[[#This Row],[ID_Antenne]],Master!D:D,Master!C:C,"Pas de correspondance") -> Pas de correspondance | J9: =_xlfn.XLOOKUP(Registre_Maintenance__2[[#This Row],[ID_Antenne]],Master!D:D,Master!F:F,"Pas de correspondance") -> Pas de correspondance | K9: =_xlfn.XLOOKUP(Registre_Maintenance__2[[#This Row],[ID_Antenne]],Master!D:D,Master!#REF!,"Pas de correspondance") -> #REF!
A10: Registre_Maintenance_Part_01.xlsx | B10: ANT-0552 | C10: Kinshasa | D10: -10.57951 | E10: 23.502314 | F10: 4G | G10: ZTE | H10: =_xlfn.XLOOKUP(Registre_Maintenance__2[[#This Row],[ID_Antenne]],Master!D:D,Master!B:B,"Pas de correspondance") -> Pas de correspondance | I10: =_xlfn.XLOOKUP(Registre_Maintenance__2[[#This Row],[ID_Antenne]],Master!D:D,Master!C:C,"Pas de correspondance") -> Pas de correspondance | J10: =_xlfn.XLOOKUP(Registre_Maintenance__2[[#This Row],[ID_Antenne]],Master!D:D,Master!F:F,"Pas de correspondance") -> Pas de correspondance | K10: =_xlfn.XLOOKUP(Registre_Maintenance__2[[#This Row],[ID_Antenne]],Master!D:D,Master!#REF!,"Pas de correspondance") -> #REF!
A11: Registre_Maintenance_Part_01.xlsx | B11: ANT-0202 | C11: Tshuapa | D11: 3.078867 | E11: 19.513651 | F11: 5G | G11: Huawei | H11: =_xlfn.XLOOKUP(Registre_Maintenance__2[[#This Row],[ID_Antenne]],Master!D:D,Master!B:B,"Pas de correspondance") -> Pas de correspondance | I11: =_xlfn.XLOOKUP(Registre_Maintenance__2[[#This Row],[ID_Antenne]],Master!D:D,Master!C:C,"Pas de correspondance") -> Pas de correspondance | J11: =_xlfn.XLOOKUP(Registre_Maintenance__2[[#This Row],[ID_Antenne]],Master!D:D,Master!F:F,"Pas de correspondance") -> Pas de correspondance | K11: =_xlfn.XLOOKUP(Registre_Maintenance__2[[#This Row],[ID_Antenne]],Master!D:D,Master!#REF!,"Pas de correspondance") -> #REF!
A12: Registre_Maintenance_Part_01.xlsx | B12: ANT-0270 | C12: Kasaï-Central | D12: -1.648264 | E12: 28.866144 | F12: 5G | G12: Ericsson | H12: =_xlfn.XLOOKUP(Registre_Maintenance__2[[#This Row],[ID_Antenne]],Master!D:D,Master!B:B,"Pas de correspondance") -> Pas de correspondance | I12: =_xlfn.XLOOKUP(Registre_Maintenance__2[[#This Row],[ID_Antenne]],Master!D:D,Master!C:C,"Pas de correspondance") -> Pas de correspondance | J12: =_xlfn.XLOOKUP(Registre_Maintenance__2[[#This Row],[ID_Antenne]],Master!D:D,Master!F:F,"Pas de correspondance") -> Pas de correspondance | K12: =_xlfn.XLOOKUP(Registre_Maintenance__2[[#This Row],[ID_Antenne]],Master!D:D,Master!#REF!,"Pas de correspondance") -> #REF!
A13: Registre_Maintenance_Part_01.xlsx | B13: ANT-0752 | C13: Nord-Kivu | D13: -3.388313 | E13: 26.838507 | F13: 5G | G13: Nokia | H13: =_xlfn.XLOOKUP(Registre_Maintenance__2[[#This Row],[ID_Antenne]],Master!D:D,Master!B:B,"Pas de correspondance") -> Pas de correspondance | I13: =_xlfn.XLOOKUP(Registre_Maintenance__2[[#This Row],[ID_Antenne]],Master!D:D,Master!C:C,"Pas de correspondance") -> Pas de correspondance | J13: =_xlfn.XLOOKUP(Registre_Maintenance__2[[#This Row],[ID_Antenne]],Master!D:D,Master!F:F,"Pas de correspondance") -> Pas de correspondance | K13: =_xlfn.XLOOKUP(Registre_Maintenance__2[[#This Row],[ID_Antenne]],Master!D:D,Master!#REF!,"Pas de correspondance") -> #REF!
... A400: Registre_Maintenance_Part_08.xlsx | B400: ANT-0357 | C400: Tanganyika | D400: -11.793894 | E400: 20.433341 | F400: 5G | G400: Nokia | H400: =_xlfn.XLOOKUP(Registre_Maintenance__2[[#This Row],[ID_Antenne]],Master!D:D,Master!B:B,"Pas de correspondance") -> Pas de correspondance | I400: =_xlfn.XLOOKUP(Registre_Maintenance__2[[#This Row],[ID_Antenne]],Master!D:D,Master!C:C,"Pas de correspondance") -> Pas de correspondance | J400: =_xlfn.XLOOKUP(Registre_Maintenance__2[[#This Row],[ID_Antenne]],Master!D:D,Master!F:F,"Pas de correspondance") -> Pas de correspondance | K400: =_xlfn.XLOOKUP(Registre_Maintenance__2[[#This Row],[ID_Antenne]],Master!D:D,Master!#REF!,"Pas de correspondance") -> #REF!

Sheet Heure_Indisponible
A3: Étiquettes de lignes | B3: Somme de Panne_Heure
A4: Bas-Uele | B4: 0.93194444
A5: Equateur | B5: 0.64166667
A6: Haut-Katanga | B6: 1.0791667
A7: Haut-Lomami | B7: 0.69861111
A8: Haut-Uele | B8: 0.70208333
A9: Ituri | B9: 0.62986111
A10: Kasai | B10: 0.59513889
A11: Kasai-Central | B11: 0.48611111
A12: Kasai-Oriental | B12: 0.39513889
A13: Kinshasa | B13: 0.69861111
A14: Kongo-Central | B14: 1.2520833
A15: Kwango | B15: 0.43125
... A30: Total général | B30: 19.040278

Sheet Sous catégorisation
A3: Étiquettes de lignes | B3: Somme de Panne_Heure
A4: Bas-Uele | B4: 0.93194444
A5: 3G | B5: 0.42361111
A6: 4G | B6: 0.19375
A7: 5G | B7: 0.31458333
A8: Equateur | B8: 0.64166667
A9: 3G | B9: 0.18611111
A10: 4G | B10: 0.081944444
A11: 5G | B11: 0.37361111
A12: Haut-Katanga | B12: 1.0791667
A13: 3G | B13: 0.28541667
A14: 4G | B14: 0.32916667
A15: 5G | B15: 0.46458333
... A106: Total général | B106: 19.040278

Sheet Master
A1: Source.Name | B1: Date_Panne | C1: ID_Client | D1: Province_RDC | E1: Heure_Panne | F1: Cell_ID | G1: Panne_Heure | H1: Duree_Panne_Min | I1: Latitude | J1: Longitude | K1: Technologie | L1: Equipementier | M1: Statut_Resolution | N1: Anciennete_Mois | O1: Anciennete_Annee | P1: Type_Forfait | Q1: Type_Clients | R1: Duree_Cumulee_Panne_Min | S1: Duree_Cumulee_Panne_Heure | T1: Facture_Mensuelle | U1: Plaintes_Service_Client | V1: Remise (%) | W1: Montant remise
A2: Logs_Reseau_Part_01.xlsx | B2: 45203 | C2: =_xlfn.XLOOKUP(Logs[[#This Row],[Province_RDC]],Clients_Log!D:D,Clients_Log!B:B,"Pas de correspondance") -> CLI-01618 | D2: =_xlfn.XLOOKUP(Logs[[#This Row],[Cell_ID]],'Registre_Maintenance'!B:B,'Registre_Maintenance'!C:C,"Pas de correspondance") -> Tanganyika | E2: 0.032638889 | F2: ANT-0465 | G2: =Logs[[#This Row],[Duree_Panne_Min]]/1440 -> 0.050694444 | H2: 73 | I2: =_xlfn.XLOOKUP(Logs[[#This Row],[Cell_ID]],'Registre_Maintenance'!B:B,'Registre_Maintenance'!D:D,"Pas de correspondance") -> -11.144149 | J2: =_xlfn.XLOOKUP(Logs[[#This Row],[Cell_ID]],'Registre_Maintenance'!B:B,'Registre_Maintenance'!E:E,"Pas de correspondance") -> 27.244659 | K2: =_xlfn.XLOOKUP(Logs[[#This Row],[Cell_ID]],'Registre_Maintenance'!B:B,'Registre_Maintenance'!F:F,"Pas de correspondance") -> 4G | L2: =_xlfn.XLOOKUP(Logs[[#This Row],[Cell_ID]],'Registre_Maintenance'!B:B,'Registre_Maintenance'!G:G,"Pas de correspondance") -> Nokia | M2: Résolu | N2: =_xlfn.XLOOKUP(Logs[[#This Row],[ID_Client]],Clients_Log!B:B,Clients_Log!E:E,"Pas de correspondance") -> 115 | O2: =IFERROR(Logs[[#This Row],[Anciennete_Mois]]/12,"") -> 9.5833333 | P2: =_xlfn.XLOOKUP(Logs[[#This Row],[ID_Client]],Clients_Log!B:B,Clients_Log!F:F,"Pas de correspondance") -> Bloqué 5Go | Q2: =IF(Logs[[#This Row],[Type_Forfait]]="Pro Monde","B2B","B2C") -> B2C | R2: =_xlfn.XLOOKUP(Logs[[#This Row],[ID_Client]],Clients_Log!B:B,Clients_Log!G:G,"Pas de correspondance") -> 176 | S2: =Logs[[#This Row],[Duree_Cumulee_Panne_Min]]/1440 -> 0.12222222 | T2: =_xlfn.XLOOKUP(Logs[[#This Row],[ID_Client]],Clients_Log!B:B,Clients_Log!H:H,"Pas de correspondance") -> 33.28 | U2: =_xlfn.XLOOKUP(Logs[[#This Row],[ID_Client]],Clients_Log!B:B,Clients_Log!I:I,"Pas de correspondance") -> 4 | V2: =IF(AND(Logs[[#This Row],[Duree_Cumulee_Panne_Heure]]>TIME(12,0,0),Logs[[#This Row],[Anciennete_Annee]]>5),0.7,IF(OR(AND(Logs[[#This Row],[Duree_Cumulee_Panne_Heure]]>=TIME(4,0,0),Logs[[#This Row],[Duree_Cumulee_Panne_Heure]]<=TIME(12,0,0)),AND(Logs[[#This Row],[Anciennete_Annee]]<5,Logs[[#This Row],[Type_Forfait]]="Premium 5G 150Go")),0.45,IF(Logs[[#This Row],[Type_Clients]]="B2B",0.1,))) -> 0 | W2: =Logs[[#This Row],[Facture_Mensuelle]]*Logs[[#This Row],[Remise (%)]] -> 0
A3: Logs_Reseau_Part_01.xlsx | B3: 45208 | C3: =_xlfn.XLOOKUP(Logs[[#This Row],[Province_RDC]],Clients_Log!D:D,Clients_Log!B:B,"Pas de correspondance") -> Pas de correspondance | D3: =_xlfn.XLOOKUP(Logs[[#This Row],[Cell_ID]],'Registre_Maintenance'!B:B,'Registre_Maintenance'!C:C,"Pas de correspondance") -> Pas de correspondance | E3: 0.30138889 | F3: ANT-0004 | G3: =Logs[[#This Row],[Duree_Panne_Min]]/1440 -> 0.026388889 | H3: 38 | I3: =_xlfn.XLOOKUP(Logs[[#This Row],[Cell_ID]],'Registre_Maintenance'!B:B,'Registre_Maintenance'!D:D,"Pas de correspondance") -> Pas de correspondance | J3: =_xlfn.XLOOKUP(Logs[[#This Row],[Cell_ID]],'Registre_Maintenance'!B:B,'Registre_Maintenance'!E:E,"Pas de correspondance") -> Pas de correspondance | K3: =_xlfn.XLOOKUP(Logs[[#This Row],[Cell_ID]],'Registre_Maintenance'!B:B,'Registre_Maintenance'!F:F,"Pas de correspondance") -> Pas de correspondance | L3: =_xlfn.XLOOKUP(Logs[[#This Row],[Cell_ID]],'Registre_Maintenance'!B:B,'Registre_Maintenance'!G:G,"Pas de correspondance") -> Pas de correspondance | M3: Résolu | N3: =_xlfn.XLOOKUP(Logs[[#This Row],[ID_Client]],Clients_Log!B:B,Clients_Log!E:E,"Pas de correspondance") -> Pas de correspondance | O3: =IFERROR(Logs[[#This Row],[Anciennete_Mois]]/12,"") | P3: =_xlfn.XLOOKUP(Logs[[#This Row],[ID_Client]],Clients_Log!B:B,Clients_Log!F:F,"Pas de correspondance") -> Pas de correspondance | Q3: =IF(Logs[[#This Row],[Type_Forfait]]="Pro Monde","B2B","B2C") -> B2C | R3: =_xlfn.XLOOKUP(Logs[[#This Row],[ID_Client]],Clients_Log!B:B,Clients_Log!G:G,"Pas de correspondance") -> Pas de correspondance | S3: =Logs[[#This Row],[Duree_Cumulee_Panne_Min]]/1440 -> #VALUE! | T3: =_xlfn.XLOOKUP(Logs[[#This Row],[ID_Client]],Clients_Log!B:B,Clients_Log!H:H,"Pas de correspondance") -> Pas de correspondance | U3: =_xlfn.XLOOKUP(Logs[[#This Row],[ID_Client]],Clients_Log!B:B,Clients_Log!I:I,"Pas de correspondance") -> Pas de correspondance | V3: =IF(AND(Logs[[#This Row],[Duree_Cumulee_Panne_Heure]]>TIME(12,0,0),Logs[[#This Row],[Anciennete_Annee]]>5),0.7,IF(OR(AND(Logs[[#This Row],[Duree_Cumulee_Panne_Heure]]>=TIME(4,0,0),Logs[[#This Row],[Duree_Cumulee_Panne_Heure]]<=TIME(12,0,0)),AND(Logs[[#This Row],[Anciennete_Annee]]<5,Logs[[#This Row],[Type_Forfait]]="Premium 5G 150Go")),0.45,IF(Logs[[#This Row],[Type_Clients]]="B2B",0.1,))) -> #VALUE! | W3: =Logs[[#This Row],[Facture_Mensuelle]]*Logs[[#This Row],[Remise (%)]] -> #VALUE!
A4: Logs_Reseau_Part_01.xlsx | B4: 45204 | C4: =_xlfn.XLOOKUP(Logs[[#This Row],[Province_RDC]],Clients_Log!D:D,Clients_Log!B:B,"Pas de correspondance") -> Pas de correspondance | D4: =_xlfn.XLOOKUP(Logs[[#This Row],[Cell_ID]],'Registre_Maintenance'!B:B,'Registre_Maintenance'!C:C,"Pas de correspondance") -> Pas de correspondance | E4: 0.9625 | F4: ANT-0977 | G4: =Logs[[#This Row],[Duree_Panne_Min]]/1440 -> 0.069444444 | H4: 100 | I4: =_xlfn.XLOOKUP(Logs[[#This Row],[Cell_ID]],'Registre_Maintenance'!B:B,'Registre_Maintenance'!D:D,"Pas de correspondance") -> Pas de correspondance | J4: =_xlfn.XLOOKUP(Logs[[#This Row],[Cell_ID]],'Registre_Maintenance'!B:B,'Registre_Maintenance'!E:E,"Pas de correspondance") -> Pas de correspondance | K4: =_xlfn.XLOOKUP(Logs[[#This Row],[Cell_ID]],'Registre_Maintenance'!B:B,'Registre_Maintenance'!F:F,"Pas de correspondance") -> Pas de correspondance | L4: =_xlfn.XLOOKUP(Logs[[#This Row],[Cell_ID]],'Registre_Maintenance'!B:B,'Registre_Maintenance'!G:G,"Pas de correspondance") -> Pas de correspondance | M4: Non Résolu | N4: =_xlfn.XLOOKUP(Logs[[#This Row],[ID_Client]],Clients_Log!B:B,Clients_Log!E:E,"Pas de correspondance") -> Pas de correspondance | O4: =IFERROR(Logs[[#This Row],[Anciennete_Mois]]/12,"") | P4: =_xlfn.XLOOKUP(Logs[[#This Row],[ID_Client]],Clients_Log!B:B,Clients_Log!F:F,"Pas de correspondance") -> Pas de correspondance | Q4: =IF(Logs[[#This Row],[Type_Forfait]]="Pro Monde","B2B","B2C") -> B2C | R4: =_xlfn.XLOOKUP(Logs[[#This Row],[ID_Client]],Clients_Log!B:B,Clients_Log!G:G,"Pas de correspondance") -> Pas de correspondance | S4: =Logs[[#This Row],[Duree_Cumulee_Panne_Min]]/1440 -> #VALUE! | T4: =_xlfn.XLOOKUP(Logs[[#This Row],[ID_Client]],Clients_Log!B:B,Clients_Log!H:H,"Pas de correspondance") -> Pas de correspondance | U4: =_xlfn.XLOOKUP(Logs[[#This Row],[ID_Client]],Clients_Log!B:B,Clients_Log!I:I,"Pas de correspondance") -> Pas de correspondance | V4: =IF(AND(Logs[[#This Row],[Duree_Cumulee_Panne_Heure]]>TIME(12,0,0),Logs[[#This Row],[Anciennete_Annee]]>5),0.7,IF(OR(AND(Logs[[#This Row],[Duree_Cumulee_Panne_Heure]]>=TIME(4,0,0),Logs[[#This Row],[Duree_Cumulee_Panne_Heure]]<=TIME(12,0,0)),AND(Logs[[#This Row],[Anciennete_Annee]]<5,Logs[[#This Row],[Type_Forfait]]="Premium 5G 150Go")),0.45,IF(Logs[[#This Row],[Type_Clients]]="B2B",0.1,))) -> #VALUE! | W4: =Logs[[#This Row],[Facture_Mensuelle]]*Logs[[#This Row],[Remise (%)]] -> #VALUE!
A5: Logs_Reseau_Part_01.xlsx | B5: 45221 | C5: =_xlfn.XLOOKUP(Logs[[#This Row],[Province_RDC]],Clients_Log!D:D,Clients_Log!B:B,"Pas de correspondance") -> Pas de correspondance | D5: =_xlfn.XLOOKUP(Logs[[#This Row],[Cell_ID]],'Registre_Maintenance'!B:B,'Registre_Maintenance'!C:C,"Pas de correspondance") -> Pas de correspondance | E5: 0.99791667 | F5: ANT-0740 | G5: =Logs[[#This Row],[Duree_Panne_Min]]/1440 -> 0.054861111 | H5: 79 | I5: =_xlfn.XLOOKUP(Logs[[#This Row],[Cell_ID]],'Registre_Maintenance'!B:B,'Registre_Maintenance'!D:D,"Pas de correspondance") -> Pas de correspondance | J5: =_xlfn.XLOOKUP(Logs[[#This Row],[Cell_ID]],'Registre_Maintenance'!B:B,'Registre_Maintenance'!E:E,"Pas de correspondance") -> Pas de correspondance | K5: =_xlfn.XLOOKUP(Logs[[#This Row],[Cell_ID]],'Registre_Maintenance'!B:B,'Registre_Maintenance'!F:F,"Pas de correspondance") -> Pas de correspondance | L5: =_xlfn.XLOOKUP(Logs[[#This Row],[Cell_ID]],'Registre_Maintenance'!B:B,'Registre_Maintenance'!G:G,"Pas de correspondance") -> Pas de correspondance | M5: En Cours | N5: =_xlfn.XLOOKUP(Logs[[#This Row],[ID_Client]],Clients_Log!B:B,Clients_Log!E:E,"Pas de correspondance") -> Pas de correspondance | O5: =IFERROR(Logs[[#This Row],[Anciennete_Mois]]/12,"") | P5: =_xlfn.XLOOKUP(Logs[[#This Row],[ID_Client]],Clients_Log!B:B,Clients_Log!F:F,"Pas de correspondance") -> Pas de correspondance | Q5: =IF(Logs[[#This Row],[Type_Forfait]]="Pro Monde","B2B","B2C") -> B2C | R5: =_xlfn.XLOOKUP(Logs[[#This Row],[ID_Client]],Clients_Log!B:B,Clients_Log!G:G,"Pas de correspondance") -> Pas de correspondance | S5: =Logs[[#This Row],[Duree_Cumulee_Panne_Min]]/1440 -> #VALUE! | T5: =_xlfn.XLOOKUP(Logs[[#This Row],[ID_Client]],Clients_Log!B:B,Clients_Log!H:H,"Pas de correspondance") -> Pas de correspondance | U5: =_xlfn.XLOOKUP(Logs[[#This Row],[ID_Client]],Clients_Log!B:B,Clients_Log!I:I,"Pas de correspondance") -> Pas de correspondance | V5: =IF(AND(Logs[[#This Row],[Duree_Cumulee_Panne_Heure]]>TIME(12,0,0),Logs[[#This Row],[Anciennete_Annee]]>5),0.7,IF(OR(AND(Logs[[#This Row],[Duree_Cumulee_Panne_Heure]]>=TIME(4,0,0),Logs[[#This Row],[Duree_Cumulee_Panne_Heure]]<=TIME(12,0,0)),AND(Logs[[#This Row],[Anciennete_Annee]]<5,Logs[[#This Row],[Type_Forfait]]="Premium 5G 150Go")),0.45,IF(Logs[[#This Row],[Type_Clients]]="B2B",0.1,))) -> #VALUE! | W5: =Logs[[#This Row],[Facture_Mensuelle]]*Logs[[#This Row],[Remise (%)]] -> #VALUE!
A6: Logs_Reseau_Part_01.xlsx | B6: 45217 | C6: =_xlfn.XLOOKUP(Logs[[#This Row],[Province_RDC]],Clients_Log!D:D,Clients_Log!B:B,"Pas de correspondance") -> Pas de correspondance | D6: =_xlfn.XLOOKUP(Logs[[#This Row],[Cell_ID]],'Registre_Maintenance'!B:B,'Registre_Maintenance'!C:C,"Pas de correspondance") -> Pas de correspondance | E6: 0.10902778 | F6: ANT-0897 | G6: =Logs[[#This Row],[Duree_Panne_Min]]/1440 -> 0.040972222 | H6: 59 | I6: =_xlfn.XLOOKUP(Logs[[#This Row],[Cell_ID]],'Registre_Maintenance'!B:B,'Registre_Maintenance'!D:D,"Pas de correspondance") -> Pas de correspondance | J6: =_xlfn.XLOOKUP(Logs[[#This Row],[Cell_ID]],'Registre_Maintenance'!B:B,'Registre_Maintenance'!E:E,"Pas de correspondance") -> Pas de correspondance | K6: =_xlfn.XLOOKUP(Logs[[#This Row],[Cell_ID]],'Registre_Maintenance'!B:B,'Registre_Maintenance'!F:F,"Pas de correspondance") -> Pas de correspondance | L6: =_xlfn.XLOOKUP(Logs[[#This Row],[Cell_ID]],'Registre_Maintenance'!B:B,'Registre_Maintenance'!G:G,"Pas de correspondance") -> Pas de correspondance | M6: Résolu | N6: =_xlfn.XLOOKUP(Logs[[#This Row],[ID_Client]],Clients_Log!B:B,Clients_Log!E:E,"Pas de correspondance") -> Pas de correspondance | O6: =IFERROR(Logs[[#This Row],[Anciennete_Mois]]/12,"") | P6: =_xlfn.XLOOKUP(Logs[[#This Row],[ID_Client]],Clients_Log!B:B,Clients_Log!F:F,"Pas de correspondance") -> Pas de correspondance | Q6: =IF(Logs[[#This Row],[Type_Forfait]]="Pro Monde","B2B","B2C") -> B2C | R6: =_xlfn.XLOOKUP(Logs[[#This Row],[ID_Client]],Clients_Log!B:B,Clients_Log!G:G,"Pas de correspondance") -> Pas de correspondance | S6: =Logs[[#This Row],[Duree_Cumulee_Panne_Min]]/1440 -> #VALUE! | T6: =_xlfn.XLOOKUP(Logs[[#This Row],[ID_Client]],Clients_Log!B:B,Clients_Log!H:H,"Pas de correspondance") -> Pas de correspondance | U6: =_xlfn.XLOOKUP(Logs[[#This Row],[ID_Client]],Clients_Log!B:B,Clients_Log!I:I,"Pas de correspondance") -> Pas de correspondance | V6: =IF(AND(Logs[[#This Row],[Duree_Cumulee_Panne_Heure]]>TIME(12,0,0),Logs[[#This Row],[Anciennete_Annee]]>5),0.7,IF(OR(AND(Logs[[#This Row],[Duree_Cumulee_Panne_Heure]]>=TIME(4,0,0),Logs[[#This Row],[Duree_Cumulee_Panne_Heure]]<=TIME(12,0,0)),AND(Logs[[#This Row],[Anciennete_Annee]]<5,Logs[[#This Row],[Type_Forfait]]="Premium 5G 150Go")),0.45,IF(Logs[[#This Row],[Type_Clients]]="B2B",0.1,))) -> #VALUE! | W6: =Logs[[#This Row],[Facture_Mensuelle]]*Logs[[#This Row],[Remise (%)]] -> #VALUE!
A7: Logs_Reseau_Part_01.xlsx | B7: 45213 | C7: =_xlfn.XLOOKUP(Logs[[#This Row],[Province_RDC]],Clients_Log!D:D,Clients_Log!B:B,"Pas de correspondance") -> CLI-01233 | D7: =_xlfn.XLOOKUP(Logs[[#This Row],[Cell_ID]],'Registre_Maintenance'!B:B,'Registre_Maintenance'!C:C,"Pas de correspondance") -> Kongo-Central | E7: 0.042361111 | F7: ANT-0737 | G7: =Logs[[#This Row],[Duree_Panne_Min]]/1440 -> 0.082638889 | H7: 119 | I7: =_xlfn.XLOOKUP(Logs[[#This Row],[Cell_ID]],'Registre_Maintenance'!B:B,'Registre_Maintenance'!D:D,"Pas de correspondance") -> -2.821152 | J7: =_xlfn.XLOOKUP(Logs[[#This Row],[Cell_ID]],'Registre_Maintenance'!B:B,'Registre_Maintenance'!E:E,"Pas de correspondance") -> 20.651419 | K7: =_xlfn.XLOOKUP(Logs[[#This Row],[Cell_ID]],'Registre_Maintenance'!B:B,'Registre_Maintenance'!F:F,"Pas de correspondance") -> 5G | L7: =_xlfn.XLOOKUP(Logs[[#This Row],[Cell_ID]],'Registre_Maintenance'!B:B,'Registre_Maintenance'!G:G,"Pas de correspondance") -> Ericsson | M7: Non Résolu | N7: =_xlfn.XLOOKUP(Logs[[#This Row],[ID_Client]],Clients_Log!B:B,Clients_Log!E:E,"Pas de correspondance") -> 101 | O7: =IFERROR(Logs[[#This Row],[Anciennete_Mois]]/12,"") -> 8.4166667 | P7: =_xlfn.XLOOKUP(Logs[[#This Row],[ID_Client]],Clients_Log!B:B,Clients_Log!F:F,"Pas de correspondance") -> Pro Monde | Q7: =IF(Logs[[#This Row],[Type_Forfait]]="Pro Monde","B2B","B2C") -> B2B | R7: =_xlfn.XLOOKUP(Logs[[#This Row],[ID_Client]],Clients_Log!B:B,Clients_Log!G:G,"Pas de correspondance") -> 333 | S7: =Logs[[#This Row],[Duree_Cumulee_Panne_Min]]/1440 -> 0.23125 | T7: =_xlfn.XLOOKUP(Logs[[#This Row],[ID_Client]],Clients_Log!B:B,Clients_Log!H:H,"Pas de correspondance") -> 74.32 | U7: =_xlfn.XLOOKUP(Logs[[#This Row],[ID_Client]],Clients_Log!B:B,Clients_Log!I:I,"Pas de correspondance") -> 1 | V7: =IF(AND(Logs[[#This Row],[Duree_Cumulee_Panne_Heure]]>TIME(12,0,0),Logs[[#This Row],[Anciennete_Annee]]>5),0.7,IF(OR(AND(Logs[[#This Row],[Duree_Cumulee_Panne_Heure]]>=TIME(4,0,0),Logs[[#This Row],[Duree_Cumulee_Panne_Heure]]<=TIME(12,0,0)),AND(Logs[[#This Row],[Anciennete_Annee]]<5,Logs[[#This Row],[Type_Forfait]]="Premium 5G 150Go")),0.45,IF(Logs[[#This Row],[Type_Clients]]="B2B",0.1,))) -> 0.45 | W7: =Logs[[#This Row],[Facture_Mensuelle]]*Logs[[#This Row],[Remise (%)]] -> 33.444
A8: Logs_Reseau_Part_01.xlsx | B8: 45202 | C8: =_xlfn.XLOOKUP(Logs[[#This Row],[Province_RDC]],Clients_Log!D:D,Clients_Log!B:B,"Pas de correspondance") -> CLI-00060 | D8: =_xlfn.XLOOKUP(Logs[[#This Row],[Cell_ID]],'Registre_Maintenance'!B:B,'Registre_Maintenance'!C:C,"Pas de correspondance") -> Kasaï-Central | E8: 0.25972222 | F8: ANT-0270 | G8: =Logs[[#This Row],[Duree_Panne_Min]]/1440 -> 0.054861111 | H8: 79 | I8: =_xlfn.XLOOKUP(Logs[[#This Row],[Cell_ID]],'Registre_Maintenance'!B:B,'Registre_Maintenance'!D:D,"Pas de correspondance") -> -1.648264 | J8: =_xlfn.XLOOKUP(Logs[[#This Row],[Cell_ID]],'Registre_Maintenance'!B:B,'Registre_Maintenance'!E:E,"Pas de correspondance") -> 28.866144 | K8: =_xlfn.XLOOKUP(Logs[[#This Row],[Cell_ID]],'Registre_Maintenance'!B:B,'Registre_Maintenance'!F:F,"Pas de correspondance") -> 5G | L8: =_xlfn.XLOOKUP(Logs[[#This Row],[Cell_ID]],'Registre_Maintenance'!B:B,'Registre_Maintenance'!G:G,"Pas de correspondance") -> Ericsson | M8: Résolu | N8: =_xlfn.XLOOKUP(Logs[[#This Row],[ID_Client]],Clients_Log!B:B,Clients_Log!E:E,"Pas de correspondance") -> 72 | O8: =IFERROR(Logs[[#This Row],[Anciennete_Mois]]/12,"") -> 6 | P8: =_xlfn.XLOOKUP(Logs[[#This Row],[ID_Client]],Clients_Log!B:B,Clients_Log!F:F,"Pas de correspondance") -> Pro Monde | Q8: =IF(Logs[[#This Row],[Type_Forfait]]="Pro Monde","B2B","B2C") -> B2B | R8: =_xlfn.XLOOKUP(Logs[[#This Row],[ID_Client]],Clients_Log!B:B,Clients_Log!G:G,"Pas de correspondance") -> 160 | S8: =Logs[[#This Row],[Duree_Cumulee_Panne_Min]]/1440 -> 0.11111111 | T8: =_xlfn.XLOOKUP(Logs[[#This Row],[ID_Client]],Clients_Log!B:B,Clients_Log!H:H,"Pas de correspondance") -> 90.13 | U8: =_xlfn.XLOOKUP(Logs[[#This Row],[ID_Client]],Clients_Log!B:B,Clients_Log!I:I,"Pas de correspondance") -> 2 | V8: =IF(AND(Logs[[#This Row],[Duree_Cumulee_Panne_Heure]]>TIME(12,0,0),Logs[[#This Row],[Anciennete_Annee]]>5),0.7,IF(OR(AND(Logs[[#This Row],[Duree_Cumulee_Panne_Heure]]>=TIME(4,0,0),Logs[[#This Row],[Duree_Cumulee_Panne_Heure]]<=TIME(12,0,0)),AND(Logs[[#This Row],[Anciennete_Annee]]<5,Logs[[#This Row],[Type_Forfait]]="Premium 5G 150Go")),0.45,IF(Logs[[#This Row],[Type_Clients]]="B2B",0.1,))) -> 0.1 | W8: =Logs[[#This Row],[Facture_Mensuelle]]*Logs[[#This Row],[Remise (%)]] -> 9.013
